2025-06-01 20:05:22,847 - ERROR - Exception occurred in during database setup: unable to open database file
2025-06-01 20:05:22,849 - ERROR - Traceback (most recent call last):
  File "/home/telmo-claro/PycharmProjects/FA_SQ_24_25_V1_1/src/database/database.py", line 14, in create
    with sqlite3.connect(self.path) as conn:
         ~~~~~~~~~~~~~~~^^^^^^^^^^^
sqlite3.OperationalError: unable to open database file

