2025-06-07 16:03:38,847 - INFO - [8e66390792b30692e51e2a8c8cc72d201cf528592c72df8accfe2d9459a4eaee] 725716b6df2a2ce3060b1681ae49712313e3156ab2af1b2ee7585b72b69dc7d5
2025-06-07 16:03:38,863 - INFO - [8e66390792b30692e51e2a8c8cc72d201cf528592c72df8accfe2d9459a4eaee] 92a824aec75ad8302e5f546fd2531c8ff87762bfd72e5050b6120a69c4a99baa
2025-06-07 16:03:38,864 - INFO - [8e66390792b30692e51e2a8c8cc72d201cf528592c72df8accfe2d9459a4eaee] 7f80d821a920baa16aca54f9d2816af25ef763dac0e91a14b00abc0f87419976
2025-06-07 16:03:38,902 - ERROR - Exception occurred in 62d9b02a491b778cf53dabbd22c6ef5b691db9126261ac878e2c236f26213622: 4ca1800417ef883aa00703957a628d7ad46ba2f155fb19c8dde52e28011a866e
2025-06-07 16:03:38,902 - ERROR - Traceback (most recent call last):
  File "C:\Users\Telmo Claro\Documents\Projects\FA_SQ_24_25_V1_1\src\database.py", line 78, in add_user
    cursor.execute(query, (Fname, Lname, Uname, Pword, Role, Rdate))
sqlite3.InterfaceError: Error binding parameter 2 - probably unsupported type.

2025-06-07 16:03:46,989 - INFO - [8e66390792b30692e51e2a8c8cc72d201cf528592c72df8accfe2d9459a4eaee] e332a6b3f0eb0ca62fc4b03f9a461db6a64486e924df8a8c24e2aca26074a2a2
2025-06-07 16:03:46,990 - INFO - [8e66390792b30692e51e2a8c8cc72d201cf528592c72df8accfe2d9459a4eaee] db6f6751311f9fdcb04948a67096a5b506522391edde8eaf28496fb140a0cd5a
2025-06-07 16:03:46,990 - ERROR - Exception occurred in 6af677308c6f8a2dd5d727347615b616bf3d95b6759581f27bfab079e7e9e4d2: e3b0c44298fc1c149afbf4c8996fb92427ae41e4649b934ca495991b7852b855
2025-06-07 16:03:46,992 - ERROR - Traceback (most recent call last):
  File "C:\Users\Telmo Claro\AppData\Local\Programs\Python\Python310\lib\site-packages\cryptography\fernet.py", line 114, in _get_unverified_token_data
    data = base64.urlsafe_b64decode(token)
  File "C:\Users\Telmo Claro\AppData\Local\Programs\Python\Python310\lib\base64.py", line 133, in urlsafe_b64decode
    return b64decode(s)
  File "C:\Users\Telmo Claro\AppData\Local\Programs\Python\Python310\lib\base64.py", line 87, in b64decode
    return binascii.a2b_base64(s)
binascii.Error: Incorrect padding

During handling of the above exception, another exception occurred:

Traceback (most recent call last):
  File "C:\Users\Telmo Claro\Documents\Projects\FA_SQ_24_25_V1_1\src\ui.py", line 31, in landing
    sa = auth.auth_super_admin(username, password)
  File "C:\Users\Telmo Claro\Documents\Projects\FA_SQ_24_25_V1_1\src\authenticator.py", line 12, in auth_super_admin
    username = helper.symmetric_decrypt(username)
  File "C:\Users\Telmo Claro\Documents\Projects\FA_SQ_24_25_V1_1\src\helper.py", line 42, in symmetric_decrypt
    decrypted = engine.decrypt(encrypted).decode()
  File "C:\Users\Telmo Claro\AppData\Local\Programs\Python\Python310\lib\site-packages\cryptography\fernet.py", line 85, in decrypt
    timestamp, data = Fernet._get_unverified_token_data(token)
  File "C:\Users\Telmo Claro\AppData\Local\Programs\Python\Python310\lib\site-packages\cryptography\fernet.py", line 116, in _get_unverified_token_data
    raise InvalidToken
cryptography.fernet.InvalidToken

