2025-06-16 18:05:19,858 - INFO - User activity logged: Super Admin, Logged in, , Low Risk
2025-06-16 18:05:19,863 - INFO - User activity logged: super_admin, Accessed Super Administrator Dashboard, , Low Risk
2025-06-16 18:05:20,933 - INFO - User activity logged: super_admin, Accessed User Management, , Low Risk
2025-06-16 18:05:31,913 - INFO - User activity logged: super_admin, Added b'gAAAAABoUEDLt_7E80A4Hz2K7pvrMFyoZUfTGi1EjXfKmWlk_wNzwIRXUkIkmVZFAeqPLs-W8zID9La_POTJUQM937lHwqgarg==', System Administrator, Low Risk
2025-06-16 18:05:47,421 - INFO - User activity logged: super_admin, Added b'gAAAAABoUEDbhGiq75KVuNR50Ut_B-JKGnuDNIz9T6yDIcjO2j2qEvedVy3jbHiTl0UFE21nkHLhXcFJw5XHMstSgl8PgAt4ZA==', Service Engineer, Low Risk
2025-06-16 18:06:05,592 - INFO - User activity logged: super_admin, Viewed users, , Low Risk
2025-06-16 18:06:10,911 - INFO - User activity logged: super_admin, Made a backup, backup_2025-06-16_18-06.zip, Low Risk
2025-06-16 18:06:14,187 - INFO - User activity logged: super_admin, Restored a backup, backup_2025-06-16_18-06.zip, Low Risk
2025-06-16 18:06:20,592 - INFO - User activity logged: super_admin, Generating one use restore code, , Low Risk
2025-06-16 18:06:25,998 - INFO - User activity logged: super_admin, Adding scooter, , Low Risk
2025-06-16 18:07:13,511 - INFO - User activity logged: super_admin, Adding traveler, , Low Risk
2025-06-16 18:08:01,380 - ERROR - User activity logged: super_admin, An unexpected error occurred in the Super Administrator Dashboard, Traceback (most recent call last):
  File "C:\Users\Telmo\OneDrive\Documents\GitHub\FA_SQ_24_25_V1_1\src\user_interface.py", line 84, in landing_super_admin
    self.data_management_super_admin(user)
  File "C:\Users\Telmo\OneDrive\Documents\GitHub\FA_SQ_24_25_V1_1\src\user_interface.py", line 329, in data_management_super_admin
    if user.view_logs(self._db, self._logger):
       ^^^^^^^^^^^^^^^^^^^^^^^^^^^^^^^^^^^^^^
  File "C:\Users\Telmo\OneDrive\Documents\GitHub\FA_SQ_24_25_V1_1\src\models.py", line 1008, in view_logs
    print(f"ID: {Helper.symmetric_decrypt(log[0])}, "
                 ^^^^^^^^^^^^^^^^^^^^^^^^^^^^^^^^
  File "C:\Users\Telmo\OneDrive\Documents\GitHub\FA_SQ_24_25_V1_1\src\helper.py", line 88, in symmetric_decrypt
    return engine.decrypt(encrypted).decode()
           ^^^^^^^^^^^^^^^^^^^^^^^^^
  File "C:\Users\Telmo\AppData\Local\Packages\PythonSoftwareFoundation.Python.3.11_qbz5n2kfra8p0\LocalCache\local-packages\Python311\site-packages\cryptography\fernet.py", line 85, in decrypt
    timestamp, data = Fernet._get_unverified_token_data(token)
                      ^^^^^^^^^^^^^^^^^^^^^^^^^^^^^^^^^^^^^^^^
  File "C:\Users\Telmo\AppData\Local\Packages\PythonSoftwareFoundation.Python.3.11_qbz5n2kfra8p0\LocalCache\local-packages\Python311\site-packages\cryptography\fernet.py", line 111, in _get_unverified_token_data
    raise TypeError("token must be bytes or str")
TypeError: token must be bytes or str
, High Risk
