2025-06-16 20:39:34,581 - INFO - User activity logged: telmoclaro, Logged in, , Low Risk
2025-06-16 20:39:34,588 - INFO - User activity logged: telmoclaro, Accessed System Administrator Dashboard, , Low Risk
2025-06-16 20:39:35,704 - INFO - User activity logged: telmoclaro, Accessed Account Features, , Low Risk
2025-06-16 20:39:36,646 - INFO - User activity logged: telmoclaro, Changing password, , Low Risk
2025-06-16 20:39:45,845 - ERROR - User activity logged: telmoclaro, An unexpected error occurred in Account Features, Traceback (most recent call last):
  File "C:\Users\Telmo\OneDrive\Documents\GitHub\FA_SQ_24_25_V1_1\src\models.py", line 1037, in change_own_password
    if Helper.verify_password(old_password, self.password_hash):  # Changed to password_hash
       ^^^^^^^^^^^^^^^^^^^^^^
AttributeError: type object 'Helper' has no attribute 'verify_password'

During handling of the above exception, another exception occurred:

Traceback (most recent call last):
  File "C:\Users\Telmo\OneDrive\Documents\GitHub\FA_SQ_24_25_V1_1\src\user_interface.py", line 393, in account_features_system_admin
    if user.change_own_password(self._db, self._logger):
       ^^^^^^^^^^^^^^^^^^^^^^^^^^^^^^^^^^^^^^^^^^^^^^^^
  File "C:\Users\Telmo\OneDrive\Documents\GitHub\FA_SQ_24_25_V1_1\src\models.py", line 1056, in change_own_password
    logger.log_error(self, f"Password change failed: {str(e)}")
TypeError: Logger.log_error() missing 1 required positional argument: 'additional_info'
, High Risk
2025-06-16 20:39:51,305 - INFO - User activity logged: telmoclaro, Accessed Account Features, , Low Risk
2025-06-16 20:39:52,468 - INFO - User activity logged: telmoclaro, Updating own profile, , Low Risk
2025-06-16 20:39:58,792 - INFO - User activity logged: telmoclaro, Changing password, , Low Risk
2025-06-16 20:40:01,695 - ERROR - User activity logged: telmoclaro, An unexpected error occurred in Account Features, Traceback (most recent call last):
  File "C:\Users\Telmo\OneDrive\Documents\GitHub\FA_SQ_24_25_V1_1\src\models.py", line 1037, in change_own_password
    if Helper.verify_password(old_password, self.password_hash):  # Changed to password_hash
       ^^^^^^^^^^^^^^^^^^^^^^
AttributeError: type object 'Helper' has no attribute 'verify_password'

During handling of the above exception, another exception occurred:

Traceback (most recent call last):
  File "C:\Users\Telmo\OneDrive\Documents\GitHub\FA_SQ_24_25_V1_1\src\user_interface.py", line 393, in account_features_system_admin
    if user.change_own_password(self._db, self._logger):
       ^^^^^^^^^^^^^^^^^^^^^^^^^^^^^^^^^^^^^^^^^^^^^^^^
  File "C:\Users\Telmo\OneDrive\Documents\GitHub\FA_SQ_24_25_V1_1\src\models.py", line 1056, in change_own_password
    logger.log_error(self, f"Password change failed: {str(e)}")
TypeError: Logger.log_error() missing 1 required positional argument: 'additional_info'
, High Risk
